<?xml version="1.0"?>
<robot name="mira">

    <material name="blue">
        <color rgba="0 0 0.8 1"/>
    </material>
    <material name="red">
        <color rgba="0.8 0 0 1"/>
    </material>
    <material name="green">
        <color rgba="0 0.8 0 1"/>
    </material>

   	<!-- * * * Link Definitions * * * -->

    <link name="base_link">
    </link>

    <link name="head_link">
        <visual>
            <origin rpy="0.0 0 0" xyz="0 0 0"/>
            <geometry>
                <mesh filename="package://my_gurdy_description/models/gurdy/meshes/gurdy_head_v2.dae"/>
            </geometry>
            <material name="red"/>
        </visual>
	</link>

    <joint name="head_joint" type="fixed">
    	<parent link="base_link"/>
    	<child link="head_link"/>
        <origin xyz="0 0 0" rpy="0 0 0"/>
	</joint>


    <!--ACA COMIENZAN los links de upperleg-->
    <link name="upperleg_M1_link">

        <visual>
            <origin rpy="0 0 0" xyz="0 0 0"/>
            <geometry>
                <mesh filename="package://my_gurdy_description/models/gurdy/meshes/gurdy_higherleg_v2.dae"/>
            </geometry>
            <material name="green"/>
        </visual>
    </link>
    <!-- This is for color and physical properties in Gazebo, color won't work with the material tag in gazebo
    only for URDF coloring -->
    <gazebo reference="upperleg_M1_link">
        <kp>1000.0</kp>
        <kd>10.0</kd>
        <mu1>10.0</mu1>
        <mu2>10.0</mu2>
        <material>Gazebo/Green</material>
    </gazebo>

    <joint name="head_upperlegM1_joint" type="revolute">
    	<parent link="head_link"/>
    	<child link="upperleg_M1_link"/>
        <origin xyz="-0.02165 -0.0125 -0.008" rpy="3.14159 -1.05879e-22 0.523599"/>
        <limit lower="-1.57" upper="0.25" effort="0.1" velocity="0.005"/>
        <axis xyz="0 1 0"/>
	</joint>

    <link name="upperleg_M2_link">

        <visual>
            <origin rpy="0 0 0" xyz="0 0 0"/>
            <geometry>
                <mesh filename="package://my_gurdy_description/models/gurdy/meshes/gurdy_higherleg_v2.dae"/>
            </geometry>
            <material name="green"/>
        </visual>
    </link>
    <!-- This is for color and physical properties in Gazebo, color won't work with the material tag in gazebo
    only for URDF coloring -->
    <gazebo reference="upperleg_M2_link">
        <kp>1000.0</kp>
        <kd>10.0</kd>
        <mu1>10.0</mu1>
        <mu2>10.0</mu2>
        <material>Gazebo/Green</material>
    </gazebo>

    <joint name="head_upperlegM2_joint" type="revolute">
    	<parent link="head_link"/>
    	<child link="upperleg_M2_link"/>
        <origin xyz="0.02165 -0.0125 -0.008" rpy="3.14159 -1.05879e-22 2.61799"/>
        <limit lower="-1.57" upper="0.25" effort="0.1" velocity="0.005"/>
        <axis xyz="0 1 0"/>
	</joint>

     <link name="upperleg_M3_link">

        <visual>
            <origin rpy="0 0 0" xyz="0 0 0"/>
            <geometry>
                <mesh filename="package://my_gurdy_description/models/gurdy/meshes/gurdy_higherleg_v2.dae"/>
            </geometry>
            <material name="green"/>
        </visual>
    </link>
    <!-- This is for color and physical properties in Gazebo, color won't work with the material tag in gazebo
    only for URDF coloring -->
    <gazebo reference="upperleg_M3_link">
        <kp>1000.0</kp>
        <kd>10.0</kd>
        <mu1>10.0</mu1>
        <mu2>10.0</mu2>
        <material>Gazebo/Green</material>
    </gazebo>

    <joint name="head_upperlegM3_joint" type="revolute">
    	<parent link="head_link"/>
    	<child link="upperleg_M3_link"/>
        <origin xyz="0 0.025 -0.008" rpy="3.14159 -0 -1.5708"/>
        <limit lower="-1.57" upper="0.25" effort="0.1" velocity="0.005"/>
        <axis xyz="0 1 0"/>
	</joint>

    <!-- ACA COMIENZA LOWRLEG LINKS-->

    <link name="lowerleg_M1_link">

        <visual>
            <origin rpy="0 0 0" xyz="0 0 0"/>
            <geometry>
                <mesh filename="package://my_gurdy_description/models/gurdy/meshes/gurdy_lowerleg_v2.dae"/>
            </geometry>
            <material name="green"/>
        </visual>
    </link>
    <!-- This is for color and physical properties in Gazebo, color won't work with the material tag in gazebo
    only for URDF coloring -->
    <gazebo reference="lowerleg_M1_link">
        <kp>1000.0</kp>
        <kd>10.0</kd>
        <mu1>10.0</mu1>
        <mu2>10.0</mu2>
        <material>Gazebo/Green</material>
    </gazebo>

    <joint name="upperlegM1_lowerlegM1_joint" type="revolute">
    	<parent link="upperleg_M1_link"/>
    	<child link="lowerleg_M1_link"/>
        <origin xyz="0 0.0095 0.06" rpy="0 -0 3.1459"/>
        <limit lower="-1.57" upper="1.57" effort="0.1" velocity="0.005"/>
        <axis xyz="0 1 0"/>
	</joint>

    <link name="lowerleg_M2_link">

        <visual>
            <origin rpy="0 0 0" xyz="0 0 0"/>
            <geometry>
                <mesh filename="package://my_gurdy_description/models/gurdy/meshes/gurdy_lowerleg_v2.dae"/>
            </geometry>
            <material name="green"/>
        </visual>
    </link>
    <!-- This is for color and physical properties in Gazebo, color won't work with the material tag in gazebo
    only for URDF coloring -->
    <gazebo reference="lowerleg_M2_link">
        <kp>1000.0</kp>
        <kd>10.0</kd>
        <mu1>10.0</mu1>
        <mu2>10.0</mu2>
        <material>Gazebo/Green</material>
    </gazebo>

    <joint name="upperlegM2_lowerlegM2_joint" type="revolute">
    	<parent link="upperleg_M2_link"/>
    	<child link="lowerleg_M2_link"/>
        <origin xyz="0 0.0095 0.06" rpy="0 -0 3.1459"/>
        <limit lower="-1.57" upper="1.57" effort="0.1" velocity="0.005"/>
        <axis xyz="0 1 0"/>
	</joint>

     <link name="lowerleg_M3_link">

        <visual>
            <origin rpy="0 0 0" xyz="0 0 0"/>
            <geometry>
                <mesh filename="package://my_gurdy_description/models/gurdy/meshes/gurdy_lowerleg_v2.dae"/>
            </geometry>
            <material name="green"/>
        </visual>
    </link>
    <!-- This is for color and physical properties in Gazebo, color won't work with the material tag in gazebo
    only for URDF coloring -->
    <gazebo reference="lowerleg_M3_link">
        <kp>1000.0</kp>
        <kd>10.0</kd>
        <mu1>10.0</mu1>
        <mu2>10.0</mu2>
        <material>Gazebo/Green</material>
    </gazebo>

    <joint name="upperlegM3_lowerlegM3_joint" type="revolute">
    	<parent link="upperleg_M3_link"/>
    	<child link="lowerleg_M3_link"/>
        <origin xyz="0 0.0095 0.06" rpy="0 -0 3.1459"/>
        <limit lower="-1.57" upper="1.57" effort="0.1" velocity="0.005"/>
        <axis xyz="0 1 0"/>
	</joint>
    
</robot>